<?xml version="1.0"?>
<robot name="ArmNewDesign">

<!-- Materials -->
  <material name="aluminum">
    <color rgba=".8 .8 .8 1"/>
  </material>

  <material name="carbon fiber">
    <color rgba="0 0 0 1"/>
  </material>

  <material name="plastic">
    <color rgba="0 0 .8 1"/>
  </material>

  <material name="rubber">
    <color rgba=".5 .5 .5 1"/>
  </material>

<!-- Links -->
  <link name="base_link">
    <visual>
      <geometry>
        <box size=".07956 .03956 1.500357"/>
      </geometry>
      <origin rpy="0 0 0" xyz="0 0 .7501785"/>
      <material name="aluminum"/>
    </visual>
  </link>

  <link name="electrical_box">
    <visual>
      <geometry>
        <box size=".65 .5 .2"/>
      </geometry>
      <origin rpy="0 0 0" xyz="0 -.2897 .1"/>
      <material name="aluminum"/>
    </visual>
  </link>

  <link name="wheel_right_front">
    <visual>
      <geometry>
        <cylinder length=".25" radius=".20"/>
      </geometry>
      <origin rpy="0 1.5707 0" xyz=".60 .80 -.15"/>
      <material name="rubber"/>
    </visual>
  </link>

  <link name="wheel_right_middle">
    <visual>
      <geometry>
        <cylinder length=".25" radius=".20"/>
      </geometry>
      <origin rpy="0 1.5707 0" xyz=".60 0.0 -.15"/>
      <material name="rubber"/>
    </visual>
  </link>

  <link name="wheel_right_back">
    <visual>
      <geometry>
        <cylinder length=".25" radius=".20"/>
      </geometry>
      <origin rpy="0 1.5707 0" xyz=".60 -.60 -.15"/>
      <material name="rubber"/>
    </visual>
  </link>

  <link name="wheel_left_front">
    <visual>
      <geometry>
        <cylinder length=".25" radius=".20"/>
      </geometry>
      <origin rpy="0 1.5707 0" xyz="-.60 .80 -.15"/>
      <material name="rubber"/>
    </visual>
  </link>

  <link name="wheel_left_middle">
    <visual>
      <geometry>
        <cylinder length=".25" radius=".20"/>
      </geometry>
      <origin rpy="0 1.5707 0" xyz="-.60 0.0 -.15"/>
      <material name="rubber"/>
    </visual>
  </link>

  <link name="wheel_left_back">
    <visual>
      <geometry>
        <cylinder length=".25" radius=".20"/>
      </geometry>
      <origin rpy="0 1.5707 0" xyz="-.60 -.60 -.15"/>
      <material name="rubber"/>
    </visual>
  </link>

  <link name="gantry_attacher">
    <visual>
      <geometry>
        <box size = ".125 .009175 .125"/>
      </geometry>
      <origin rpy="0 0 0" xyz="0 .0367325 0"/>
      <material name="aluminum"/>
    </visual>
  </link>

  <link name="arm01">
    <visual>
      <geometry>
        <cylinder length=".0635" radius=".0238125"/>
      </geometry>
      <origin rpy="1.57079 0 0" xyz="0 .07307 0"/>
      <material name="aluminum"/>
    </visual>
  </link> 


  <link name="bracket_top01">
    <visual>
      <geometry>
        <box size=".0762 .0762 .0762"/>
      </geometry>
      <origin rpy="0 0 0" xyz="0 .14292 0"/>
      <material name="aluminum"/>
    </visual>
  </link>
  <link name="bracket_bottom01">
    <visual>
      <geometry>
        <box size=".0762 .0762 .0762"/>
      </geometry>
      <material name="aluminum"/>
      <origin rpy="0 0 0" xyz="0 0 0"/>
    </visual>
  </link>

  <link name="arm02">
    <visual>
      <geometry>
        <cylinder length=".378" radius=".0333375"/>
      </geometry>
      <origin rpy="1.57079 0 0" xyz="0 .2271 0"/>
      <material name="carbon fiber"/>
    </visual>
  </link>  

  <link name="bracket_bottom02">
    <visual>
      <geometry>
        <box size=".0762 .0762 .0762"/>
      </geometry>
      <material name="aluminum"/>
      <origin rpy="0 0 0" xyz="0 .4542 0"/>
    </visual>
  </link>
  <link name="bracket_top02">
    <visual>
      <geometry>
        <box size=".0635 .0635 .0635"/>
      </geometry>
      <origin rpy="0 0 0" xyz="0 0 0"/>
      <material name="aluminum"/>
    </visual>
  </link>

  <link name="arm03">
    <visual>
      <geometry>
        <cylinder length=".410244" radius=".0249555"/>
      </geometry>
      <origin rpy="1.57079 0 0" xyz="0 .236872 0"/>
      <material name="carbon fiber"/>
    </visual>
  </link>  

  <link name="bracket_top03">
    <visual>
      <geometry>
        <box size=".0762 .0762 .0762"/>
      </geometry>
      <origin rpy="0 0 0" xyz="0 .4799842 0"/>
      <material name="aluminum"/>
    </visual>
  </link>
  <link name="bracket_bottom03">
    <visual>
      <geometry>
        <box size=".0635 .0635 .0635"/>
      </geometry>
      <material name="aluminum"/>
      <origin rpy="0 0 0" xyz="0 0 0"/>
    </visual>
  </link>

  <link name="bracket_right04">
    <visual>
      <geometry>
        <box size=".0762 .0762 .0762"/>
      </geometry>
      <origin rpy="0 0 0" xyz="0 .06985 -.00635"/>
      <material name="aluminum"/>
    </visual>
  </link>

  <link name="bracket_left04">
    <visual>
      <geometry>
        <box size=".0635 .0635 .0635"/>
      </geometry>
      <origin rpy="0 0 0" xyz="0 0 0"/>
      <material name="aluminum"/>
    </visual>
  </link>

  <link name="arm05_01">
    <visual>
      <geometry>
        <cylinder length=".042167" radius=".0260375"/>
      </geometry>
      <origin rpy="1.57079 0 0" xyz="0 .0528335 0"/>
      <material name="aluminum"/>
    </visual>
  </link>  

  <link name="arm05_02">
    <visual>
      <geometry>
        <cylinder length=".104338" radius=".0260375"/>
      </geometry>
      <origin rpy="1.57079 0 0" xyz="0 0 0"/>
      <material name="carbon fiber"/>
    </visual>
  </link>  

  <link name="end_effector_base">
    <visual>
      <geometry>
        <box size=".343940 .064724 .050526"/>
      </geometry>
      <origin rpy="0 0 0" xyz="0 .084531 0"/>
      <material name="aluminum"/>
    </visual>
  </link>  

  <link name="right_gripper">
    <visual>
      <geometry>
        <box size=".033655 .139876 .025654"/>
      </geometry>
      <origin rpy="0 0 0" xyz="0 .069938 0"/>
      <material name="plastic"/>
    </visual>
  </link>
  
  <link name="left_gripper">
    <visual>
      <geometry>
        <box size=".033655 .139876 .025654"/>
      </geometry>
      <origin rpy="0 0 0" xyz="0 .069938 0"/>
      <material name="plastic"/>
    </visual>
  </link>

<!-- Joints 
  <limit effort="1000.0" lower="" upper="" velocity=""/>
  <origin rpy="0 0 0" xyz=""/>
  <axis xyz=""/>
-->
  <joint name="base_joint" type="prismatic">
    <parent link="base_link"/>
    <child link="gantry_attacher"/>
    <limit effort="1000.0" lower="0.0625" upper="1.4375" velocity="0.5"/>
    <origin rpy="0 0 0" xyz="0 0 0"/> 
    <axis xyz="0 0 1"/>
  </joint>
  <joint name="electrical_box_joint" type="fixed">
    <parent link="base_link"/>
    <child link="electrical_box"/>
  </joint>
  <joint name="wheel_rf_joint" type="fixed">
    <parent link="base_link"/>
    <child link="wheel_right_front"/>
  </joint>
  <joint name="wheel_rm_joint" type="fixed">
    <parent link="base_link"/>
    <child link="wheel_right_middle"/>
  </joint>
  <joint name="wheel_rb_joint" type="fixed">
    <parent link="base_link"/>
    <child link="wheel_right_back"/>
  </joint>
  <joint name="wheel_lf_joint" type="fixed">
    <parent link="base_link"/>
    <child link="wheel_left_front"/>
  </joint>
  <joint name="wheel_lm_joint" type="fixed">
    <parent link="base_link"/>
    <child link="wheel_left_middle"/>
  </joint>
  <joint name="wheel_lb_joint" type="fixed">
    <parent link="base_link"/>
    <child link="wheel_left_back"/>
  </joint>
  <joint name="gantry_attcher_arm01_joint" type="fixed">
    <parent link="gantry_attacher"/>
    <child link="arm01"/>
  </joint>
  <joint name="arm01_bracket01_joint" type="fixed">
    <parent link="arm01"/>
    <child link="bracket_top01"/>
  </joint>
  <joint name="bracket01_joint" type="revolute">
    <parent link="bracket_top01"/>
    <child link="bracket_bottom01"/>
    <limit effort="1000.0" lower="-2.094395" upper="2.094395" velocity="0.5"/>
    <origin rpy="0 0 0" xyz="0 .14292 -.094615"/>
    <axis xyz="0 0 1"/>
  </joint>
  <joint name="bracket01_arm02_joint" type="fixed">
    <parent link="bracket_bottom01"/>
    <child link="arm02"/>
  </joint>
  <joint name="arm02_bracket02_joint" type="fixed">
    <parent link="arm02"/>
    <child link="bracket_bottom02"/>
  </joint>
  <joint name="bracket02_joint" type="revolute">
    <parent link="bracket_bottom02"/>
    <child link="bracket_top02"/>
    <limit effort="1000.0" lower="-2.879793" upper="2.879793" velocity="0.5"/>
    <origin rpy="0 0 0" xyz="0 .4542 0.088262"/>
    <axis xyz="0 0 1"/>
  </joint>
  <joint name="bracket02_arm03_joint" type="fixed">
    <parent link="bracket_top02"/>
    <child link="arm03"/>
  </joint>
  <joint name="arm03_bracket_03_joint" type="fixed">
    <parent link="arm03"/>
    <child link="bracket_top03"/>
  </joint>
  <joint name="bracket03_joint" type="revolute">
    <parent link="bracket_top03"/>
    <child link="bracket_bottom03"/>
    <limit effort="1000.0" lower="-2.879793" upper="2.879793" velocity="0.5"/>
    <origin rpy="0 0 0" xyz="0 .4799842 -.08825"/>
    <axis xyz="0 0 1"/>
  </joint>
  <joint name="bracket03_bracket04_joint" type="fixed">
    <parent link="bracket_bottom03"/>
    <child link="bracket_right04"/>
  </joint>
  <joint name="bracket04_joint" type="revolute">
    <parent link="bracket_right04"/>
    <child link="bracket_left04"/>
    <limit effort="1000.0" lower="-2.879793" upper="2.879793" velocity="0.5"/>
    <origin rpy="0 0 0" xyz="-.06985 .06985 0"/>
    <axis xyz="1 0 0"/>
  </joint>
  <joint name="bracket04_arm05_01_joint" type="fixed">
    <parent link="bracket_left04"/>
    <child link="arm05_01"/>
  </joint>
  <joint name="arm05_joint" type="revolute">
    <parent link="arm05_01"/>
    <child link="arm05_02"/>
    <limit effort="1000.0" lower="-2.879793" upper="2.879793" velocity="0.5"/>
    <origin rpy="0 0 0" xyz="0 .126086 0"/>
    <axis xyz="0 1 0"/>
  </joint>
  <joint name="arm05_end_effector_joint" type="fixed">
    <parent link="arm05_02"/>
    <child link="end_effector_base"/>
  </joint>
  <joint name="gripper_joint" type="prismatic">
    <parent link="end_effector_base"/>
    <child link="right_gripper"/>
    <limit effort="1000.0" lower="0.0" upper="0.138315" velocity="3.75"/>
    <origin xyz=".0168275 .116893 0"/>
    <axis xyz="1 0 0"/>
  </joint>
  <joint name="gripper_mimic_joint" type="prismatic">
    <parent link="end_effector_base"/>
    <child link="left_gripper"/>
    <mimic joint="gripper_joint"/>
    <limit effort="1000.0" lower="0.0" upper="0.138315" velocity="3.75"/>
    <origin xyz="-.0168275 .116893 0"/>
    <axis xyz="-1 0 0"/>
  </joint>
</robot>